Workbook

Sheet Assumptions
A1: TechCElerate — Financial Model Assumptions | All inputs in Blue | Yellow background = key assumption
A2: 🔵 Blue = Input (change to model scenarios) | ⚫ Black = Formula | 🟡 Yellow background = key assumption
A3: PRICING TIERS — Red / White / Blue Founding Member Launch
A4: Parameter | B4: Value | C4: Unit | D4: Notes
A5: 🔴 Red — Founders for Life price | B5: 250 | C5: $ | D5: One-time lifetime payment. Cap: 250 subscribers.
A6: 🔴 Red — Subscriber cap | B6: 250 | C6: subscribers | D6: Closes Aug 4, 2026 OR sellout
A7: ⚪ White — Half Price for Life (annual, locked for life) | B7: 24.99 | C7: $/yr | D7: Price locked forever at $24.99/yr. Cap: 250 subscribers.
A8: ⚪ White — Subscriber cap | B8: 250 | C8: subscribers | D8: Closes Aug 18, 2026 OR sellout
A9: 🔵 Blue — Founding Rate for Life (annual, locked for life) | B9: 34.99 | C9: $/yr | D9: Price locked forever at $34.99/yr. Cap: 250 subscribers.
A10: 🔵 Blue — Subscriber cap | B10: 250 | C10: subscribers | D10: Closes Sep 1, 2026 OR sellout
A11: 🇺🇸 250th Extended offer (Sep 2 – Dec 31, 2026) | B11: 39.99 | C11: $/yr | D11: Sep 2 – Dec 31, 2026 HARD CUTOFF. Converts to Standard ($49.99) Jan 2027.
A12: 📊 Standard price (Jan 1, 2027+) | B12: 49.99 | C12: $/yr | D12: Permanent base price Jan 1, 2027+
A13: 🎓 Student/new grad — Year 1 | B13: 0 | C13: $/yr | D13: Free with .edu email or grad date within 12 months
A14: 🎓 Student — Year 2+ conversion price | B14: 49.99 | C14: $/yr | D14: Converts to Standard rate
A15: 📅 Soft launch date | B15: May 15, 2026 | C15: date | D15: Site live, beta testing, email list building
A16: 🎆 Founding tiers open | B16: Jul 4, 2026 | C16: date | D16: Marketing event — America's 250th
A18: SUBSCRIBER GROWTH — Monthly New Subscriber Assumptions
A19: Parameter | B19: Value | C19: Unit | D19: Notes
A20: Founding period (Jul–Sep 2026) — new standard subs/mo | B20: 0 | C20: subs/mo | D20: During founding period, focus is on tier sellout
A21: Extended period (Sep–Dec 2026) — new subs/mo at $25 | B21: 100 | C21: subs/mo | D21: Conservative: word-of-mouth + early marketing
A22: 2027 Q1 — new standard subs/mo | B22: 75 | C22: subs/mo | D22: Post-launch ramp, organic + SEO
A23: 2027 Q2 — new standard subs/mo | B23: 125 | C23: subs/mo | D23: Marketing engine warming up
A24: 2027 Q3-Q4 — new standard subs/mo | B24: 175 | C24: subs/mo | D24: Affiliate + paid ads contributing
A25: Annual churn — White/Blue tiers (permanent lock) | B25: 0.1 | C25: % | D25: 10% — permanent price lock = lower churn, but not zero
A26: Annual churn — Extended ($25) tier | B26: 0.12 | C26: % | D26: 12% — year 1 rate, then converts to Standard pricing Jan 2027
A27: Annual churn — Standard tier | B27: 0.18 | C27: % | D27: 18% — industry standard for subscription CE
A28: Student Year 1→2 conversion rate | B28: 0.25 | C28: % | D28: 25% of free students convert to paid Year 2
A29: New students/month (free, .edu) | B29: 20 | C29: subs/mo | D29: Starting at launch — RT programs outreach
A31: COST STRUCTURE — Platform Fixed + Variable Costs
A32: Parameter | B32: Value | C32: Unit | D32: Notes
A33: PLATFORM FIXED COSTS (Annual) | D33: TOTAL FIXED: $1,239/yr (~$103/mo). IP fee REMOVED — General Sponsor pays per-course only.
A34: Learning Templates hosting | B34: 288 | C34: $/yr | D34: 8 CPU Standard dedicated server
A35: LearnDash (1 license) | B35: 189 | C35: $/yr | D35: Keep primary subscription #541384
A36: Uncanny Owl All Access | B36: 499 | C36: $/yr | D36: CE Credits, Toolkit, Groups, Codes, Reporting
A37: WP Rocket (1 of 3 slots) | B37: 60 | C37: $/yr | D37: 1/3 of $180 annual — TechCElerate share
A38: Iubenda (1 site) | B38: 159 | C38: $/yr | D38: Privacy/legal compliance
A39: MonsterInsights (CUT AT RENEWAL — GA4 replaces) | B39: 0 | C39: $/yr | D39: CANCELLED — GA4 is free replacement. $799/yr saved.
A40: ASRT — NO annual fee (General Sponsor status) | B40: 0 | C40: $/yr | D40: CONFIRMED: TechCElerate is General Sponsor, NOT Institutional Provider. IP is for hospital employee-only CE. Cost is per-course only (see Content Costs below).
A41: Amazon SES email delivery | B41: 24 | C41: $/yr | D41: ~$2/mo at launch volume
A42: Domain (Name.com) | B42: 20 | C42: $/yr | D42: techcelerate-ce.com annual renewal
...

Sheet Launch Revenue
A1: TechCElerate — Founding Member Launch Revenue Model | July 4, 2026 | Standard: $49.99/yr
A3: Tier | B3: Price | C3: Cap | D3: Sell-Through % | E3: Subscribers | F3: Year 1 Revenue | G3: Year 2 Revenue | H3: Notes
A4: 🔴 Red — Founders for Life | B4: 250 | C4: 250 | D4: 0.9 | E4: =C4*D4 -> 225 | F4: =B4*C4*D4 -> 56250 | G4: 0 | H4: One-time payment. No Year 2 revenue. 90% sell-through assumption.
A5: ⚪ White — Half Price for Life | B5: 24.99 | C5: 250 | D5: 0.85 | E5: =C5*D5 -> 212.5 | F5: =B5*C5*D5 -> 5310.375 | G5: =B5*C5*D5*(1-0.1) -> 4779.3375 | H5: Annual recurring, price locked FOREVER at $24.99/yr. 10% churn Y2.
A6: 🔵 Blue — Founding Rate for Life | B6: 34.99 | C6: 250 | D6: 0.8 | E6: =C6*D6 -> 200 | F6: =B6*C6*D6 -> 6998 | G6: =B6*C6*D6*(1-0.1) -> 6298.2 | H6: Annual recurring, price locked FOREVER at $34.99/yr. 10% churn Y2.
A7: 🇺🇸 250th Extended ($39.99/yr) | B7: 39.99 | C7: 500 | D7: 0.7 | E7: =C7*D7 -> 350 | F7: =B7*C7*D7 -> 13996.5 | G7: =49.99*C7*D7*(1-0.18) -> 14347.13 | H7: Sep 2 – Dec 31, 2026. Hard cutoff. Converts to Standard ($49.99) Jan 2027.
A8: TOTAL — Founding + Extended Period | E8: =SUM(E4:E7) -> 987.5 | F8: =SUM(F4:F7) -> 82554.875 | G8: =SUM(G4:G7) -> 25424.667 | H8: Standard subscribers (Jan 2027+) are additive on top of this base
A10: KEY LAUNCH INSIGHTS
A11: If all tiers sell out (100%): | B11: =250*250 + 250*24.99 + 250*34.99 + 500*39.99 -> 97490 | C11: Y1 gross revenue at full sellout
A12: Break-even subscriber count (covering platform fixed costs only ~$175/mo): | B12: ~11 subscribers | C12: At ANY price tier
A13: Lifetime member break-even vs. Standard ($39.99/yr): | B13: ~5.0 years | C13: Year 6+ a $250 Red member costs more than they paid (at $49.99 equiv.)
A14: Red tier: year they become 'unprofitable': | B14: 2031 | C14: After 5.0 years at $49.99 equivalent value
A15: Max founding period revenue (full sellout + 500 extended): | C15: See cell F above

Sheet Monthly P&L
A1: TechCElerate — Monthly P&L | May 2026 – Oct 2027 | 18-Month View
A2: LINE ITEM | B2: May-26 | C2: Jun-26 | D2: Jul-26 | E2: Aug-26 | F2: Sep-26 | G2: Oct-26 | H2: Nov-26 | I2: Dec-26 | J2: Jan-27 | K2: Feb-27 | L2: Mar-27 | M2: Apr-27 | N2: May-27 | O2: Jun-27 | P2: Jul-27 | Q2: Aug-27 | R2: Sep-27 | S2: Oct-27 | T2: 18-Mo Total
A3: 🔴 Pre-launch (May–Jun) | 🔵 Founding Tiers Open (Jul–Sep) | 🟠 Extended $39.99 (Oct–Dec 2026) | ⚫ Standard $49.99 (Jan 2027+)
A4: REVENUE
A5: Red — One-time lifetime sales | B5: 0 | C5: 0 | D5: 18750 | E5: 25000 | F5: 12500 | G5: 0 | H5: 0 | I5: 0 | J5: 0 | K5: 0 | L5: 0 | M5: 0 | N5: 0 | O5: 0 | P5: 0 | Q5: 0 | R5: 0 | S5: 0 | T5: =SUM(B5:S5) -> 56250
A6: White — Monthly recurring ($24.99/yr, permanent) | B6: 0 | C6: 0 | D6: 104 | E6: 312 | F6: 441 | G6: 439 | H6: 439 | I6: 437 | J6: 435 | K6: 433 | L6: 431 | M6: 429 | N6: 429 | O6: 427 | P6: 425 | Q6: 423 | R6: 421 | S6: 419 | T6: =SUM(B6:S6) -> 6444
A7: Blue — Monthly recurring ($34.99/yr, permanent) | B7: 0 | C7: 0 | D7: 146 | E7: 379 | F7: 580 | G7: 574 | H7: 569 | I7: 566 | J7: 560 | K7: 557 | L7: 551 | M7: 548 | N7: 542 | O7: 539 | P7: 534 | Q7: 531 | R7: 525 | S7: 522 | T7: =SUM(B7:S7) -> 8223
A8: 250th Extended ($39.99/yr → $49.99 Standard Jan 2027) | B8: 0 | C8: 0 | D8: 0 | E8: 0 | F8: 167 | G8: 497 | H8: 826 | I8: 1150 | J8: 1421 | K8: 1400 | L8: 1383 | M8: 1366 | N8: 1350 | O8: 1337 | P8: 1321 | Q8: 1304 | R8: 1287 | S8: 1271 | T8: =SUM(B8:S8) -> 16080
A9: Standard ($49.99/yr) | B9: 0 | C9: 0 | D9: 0 | E9: 0 | F9: 0 | G9: 0 | H9: 0 | I9: 0 | J9: 312 | K9: 725 | L9: 1129 | M9: 1633 | N9: 2129 | O9: 2724 | P9: 3308 | Q9: 3987 | R9: 4657 | S9: 5316 | T9: =SUM(B9:S9) -> 25920
A10: Student (Free Year 1 → converts Yr 2) | B10: 0 | C10: 0 | D10: 0 | E10: 0 | F10: 0 | G10: 0 | H10: 0 | I10: 0 | J10: 0 | K10: 0 | L10: 0 | M10: 0 | N10: 0 | O10: 0 | P10: 0 | Q10: 0 | R10: 0 | S10: 0 | T10: =SUM(B10:S10) -> 0
A11: TOTAL REVENUE | B11: 0 | C11: 0 | D11: 19000 | E11: 25691 | F11: 13688 | G11: 1510 | H11: 1834 | I11: 2153 | J11: 2728 | K11: 3115 | L11: 3494 | M11: 3976 | N11: 4450 | O11: 5027 | P11: 5588 | Q11: 6245 | R11: 6890 | S11: 7528 | T11: =SUM(B11:S11) -> 112917
A13: COSTS
A14: Platform fixed (hosting, licenses, ASRT IP) | B14: 103 | C14: 103 | D14: 103 | E14: 103 | F14: 103 | G14: 103 | H14: 103 | I14: 103 | J14: 103 | K14: 103 | L14: 103 | M14: 103 | N14: 103 | O14: 103 | P14: 103 | Q14: 103 | R14: 103 | S14: 103 | T14: =SUM(B14:S14) -> 1854
A15: Content: pre-launch audit & refresh (20 courses) | B15: 3000 | C15: 3000 | D15: 0 | E15: 0 | F15: 0 | G15: 0 | H15: 0 | I15: 0 | J15: 0 | K15: 0 | L15: 0 | M15: 0 | N15: 0 | O15: 0 | P15: 0 | Q15: 0 | R15: 0 | S15: 0 | T15: =SUM(B15:S15) -> 6000
A16: ASRT submission fees (first 6 courses) | B16: 0 | C16: 675 | D16: 675 | E16: 0 | F16: 0 | G16: 0 | H16: 0 | I16: 0 | J16: 0 | K16: 0 | L16: 0 | M16: 0 | N16: 0 | O16: 0 | P16: 0 | Q16: 0 | R16: 0 | S16: 0 | T16: =SUM(B16:S16) -> 1350
A17: New course pipeline (6/mo × $675 fully loaded) | B17: 0 | C17: 0 | D17: 4050 | E17: 4050 | F17: 4050 | G17: 4050 | H17: 4050 | I17: 4050 | J17: 4050 | K17: 4050 | L17: 4050 | M17: 4050 | N17: 4050 | O17: 4050 | P17: 4050 | Q17: 4050 | R17: 4050 | S17: 4050 | T17: =SUM(B17:S17) -> 64800
A18: Stripe processing fees (~3.2% blended) | B18: 0 | C18: 0 | D18: 608 | E18: 822 | F18: 438 | G18: 48 | H18: 59 | I18: 69 | J18: 87 | K18: 100 | L18: 112 | M18: 127 | N18: 142 | O18: 161 | P18: 179 | Q18: 200 | R18: 220 | S18: 241 | T18: =SUM(B18:S18) -> 3613
A19: Support cost ($1.50/sub/yr blended) | B19: 0 | C19: 0 | D19: 22 | E19: 57 | F19: 86 | G19: 98 | H19: 110 | I19: 121 | J19: 130 | K19: 141 | L19: 152 | M19: 166 | N19: 180 | O19: 198 | P19: 214 | Q19: 234 | R19: 253 | S19: 272 | T19: =SUM(B19:S19) -> 2434
A20: Claude API (content generation) | B20: 0 | C20: 0 | D20: 75 | E20: 75 | F20: 75 | G20: 75 | H20: 75 | I20: 75 | J20: 75 | K20: 75 | L20: 75 | M20: 75 | N20: 75 | O20: 75 | P20: 75 | Q20: 75 | R20: 75 | S20: 75 | T20: =SUM(B20:S20) -> 1200
A21: Catalyst management fee (tiered) | B21: 0 | C21: 0 | D21: 2500 | E21: 2500 | F21: 2500 | G21: 0 | H21: 0 | I21: 0 | J21: 0 | K21: 0 | L21: 0 | M21: 0 | N21: 0 | O21: 0 | P21: 0 | Q21: 1500 | R21: 1500 | S21: 1500 | T21: =SUM(B21:S21) -> 12000
A22: TOTAL COSTS | B22: 3103 | C22: 3778 | D22: 8033 | E22: 7607 | F22: 7252 | G22: 4374 | H22: 4397 | I22: 4418 | J22: 4445 | K22: 4469 | L22: 4492 | M22: 4521 | N22: 4550 | O22: 4587 | P22: 4621 | Q22: 6162 | R22: 6201 | S22: 6241 | T22: =SUM(B22:S22) -> 93251
A24: OPERATING INCOME (EBITDA PROXY)
A25: Operating Income / (Loss) | B25: -3103 | C25: -3778 | D25: 10967 | E25: 18084 | F25: 6436 | G25: -2864 | H25: -2563 | I25: -2265 | J25: -1717 | K25: -1354 | L25: -998 | M25: -545 | N25: -100 | O25: 440 | P25: 967 | Q25: 83 | R25: 689 | S25: 1287 | T25: =SUM(B25:S25) -> 19666
A26: Operating Margin % | B26: 0 | C26: 0 | D26: 57.7 | E26: 70.4 | F26: 47 | G26: -189.7 | H26: -139.7 | I26: -105.2 | J26: -62.9 | K26: -43.5 | L26: -28.6 | M26: -13.7 | N26: -2.2 | O26: 8.8 | P26: 17.3 | Q26: 1.3 | R26: 10 | S26: 17.1
A28: SUBSCRIBER COUNTS (End of Month)
A29: Red (cumulative) | B29: 0 | C29: 0 | D29: 75 | E29: 175 | F29: 224 | G29: 223 | H29: 222 | I29: 221 | J29: 220 | K29: 220 | L29: 219 | M29: 218 | N29: 217 | O29: 216 | P29: 215 | Q29: 214 | R29: 213 | S29: 213
A30: White (cumulative) | B30: 0 | C30: 0 | D30: 50 | E30: 150 | F30: 212 | G30: 211 | H30: 211 | I30: 210 | J30: 209 | K30: 208 | L30: 207 | M30: 206 | N30: 206 | O30: 205 | P30: 204 | Q30: 203 | R30: 202 | S30: 201
A31: Blue (cumulative) | B31: 0 | C31: 0 | D31: 50 | E31: 130 | F31: 199 | G31: 197 | H31: 195 | I31: 194 | J31: 192 | K31: 191 | L31: 189 | M31: 188 | N31: 186 | O31: 185 | P31: 183 | Q31: 182 | R31: 180 | S31: 179
A32: 250th Extended (cumulative) | B32: 0 | C32: 0 | D32: 0 | E32: 0 | F32: 50 | G32: 149 | H32: 248 | I32: 345 | J32: 341 | K32: 336 | L32: 332 | M32: 328 | N32: 324 | O32: 321 | P32: 317 | Q32: 313 | R32: 309 | S32: 305
A33: Standard (cumulative) | B33: 0 | C33: 0 | D33: 0 | E33: 0 | F33: 0 | G33: 0 | H33: 0 | I33: 0 | J33: 75 | K33: 174 | L33: 271 | M33: 392 | N33: 511 | O33: 654 | P33: 794 | Q33: 957 | R33: 1118 | S33: 1276
A34: TOTAL PAYING SUBSCRIBERS | B34: 0 | C34: 0 | D34: 175 | E34: 455 | F34: 685 | G34: 780 | H34: 876 | I34: 970 | J34: 1037 | K34: 1129 | L34: 1218 | M34: 1332 | N34: 1444 | O34: 1581 | P34: 1713 | Q34: 1869 | R34: 2022 | S34: 2174

Sheet Break-Even & Unit Economics
A1: TechCElerate — Break-Even Analysis & Unit Economics
A3: BREAK-EVEN: How many subscribers needed to cover costs?
A4: Scenario | B4: $34.99/yr (Blue) | C4: $39.99/yr (Extended) | D4: $49.99/yr (Standard) | E4: $250 one-time (Red) | F4: Notes
A5: Platform fixed only (~$1,239/yr) | B5: 35 | C5: 31 | D5: 25 | E5: 5 | F5: Hosting, licenses, SES, domain. IP fee removed — General Sponsor.
A6: Platform + ASRT submissions ($3,450 yr1 add'l) | B6: 74 | C6: 65 | D6: 52 | E6: 10 | F6: Platform + ASRT first 6 course submissions ($1,350 total)
A7: Platform + content refresh ($6,000 one-time) | B7: 207 | C7: 181 | D7: 145 | E7: 29 | F7: Platform + 20-course launch refresh ($6,000 one-time)
A8: All-in Year 1 (platform + content + ASRT) | B8: 245 | C8: 215 | D8: 172 | E8: 34 | F8: All-in Year 1 (platform + content + ASRT submissions)
A9: All-in Year 1 + $18k Catalyst fee (post-launch) | B9: 760 | C9: 665 | D9: 532 | E9: 106 | F9: $1,500/mo × 12 = $18k Catalyst management fee included
A10: Steady-state Year 2+ (no one-time costs) | B10: 1939 | C10: 1696 | D10: 1357 | E10: N/A | F10: Platform ($1,239) + pipeline ($4,050×12=$48,600) + $18k Catalyst. No annual IP fee.
A12: UNIT ECONOMICS PER SUBSCRIBER (LIFETIME VALUE)
A13: Metric | B13: Red ($250 LTD) | C13: White ($24.99/yr) | D13: Blue ($34.99/yr, permanent) | E13: Standard ($49.99) | F13: Notes
A14: Annual revenue per sub (Yr 1) | B14: $250 (one-time) | C14: $24.99 | D14: $34.99 | E14: $49.99
A15: Annual revenue per sub (Yr 2+) | B15: $0 | C15: $24.99 | D15: $34.99 | E15: $49.99 | F15: White and Blue are permanent locks — price never changes
A16: Stripe fee per transaction | B16: ~$7.55 | C16: ~$1.02/yr | D16: ~$1.31/yr | E16: ~$1.75/yr | F16: 2.9% + $0.30
A17: Support cost per sub/year | B17: $1.50 | C17: $1.50 | D17: $1.50 | E17: $1.50 | F17: AI-assisted, 80% automated
A18: Content cost (allocated per sub) | B18: ~$6.00 | C18: ~$6.00 | D18: ~$6.00 | E18: ~$6.00 | F18: $6k ÷ 1,000 subs est. Year 1
A19: Contribution margin Yr 1 | B19: ~$234 | C19: ~$16.47 | D19: ~$26.18 | E19: ~$40.74 | F19: After variable costs
A20: Contribution margin % | B20: ~93.7% | C20: ~65.9% | D20: ~74.8% | E20: ~81.5%
A21: Avg years as subscriber (est.) | B21: Lifetime | C21: ~10 yrs (10% churn) | D21: ~10 yrs (10% churn) | E21: ~5.6 yrs (18% churn) | F21: 1/churn rate
A22: LTV (lifetime value) | B22: ~$250 | C22: ~$250 | D22: ~$350 | E22: ~$278 | F22: Simplified; excludes time value
A23: CAC target (< 25% LTV) | B23: <$62 | C23: <$62 | D23: <$87 | E23: <$69 | F23: Target acquisition cost ceiling
A25: YEAR 1-3 SUMMARY REVENUE PROJECTION
A26: Revenue Stream | B26: Year 1 (2026) | C26: Year 2 (2027) | D26: Year 3 (2028) | E26: 3-Year Total | F26: Notes
A27: Red founding members (one-time) | B27: 56250 | C27: 0 | D27: 0 | E27: =B27+C27+D27 -> 56250 | F27: 250×$250×90% sell-through
A28: White ($24.99/yr, permanent) | B28: 5310 | C28: 4779 | D28: 4301 | E28: =B28+C28+D28 -> 14390 | F28: ~10% annual churn; permanent $24.99 lock
A29: Blue ($34.99/yr, permanent) | B29: 6998 | C29: 6298 | D29: 5668 | E29: =B29+C29+D29 -> 18964 | F29: Permanent $34.99/yr lock; 10% churn
A30: 250th Extended ($39.99 → $49.99 Standard Jan 2027) | B30: 11997 | C30: 17245 | D30: 15801 | E30: =B30+C30+D30 -> 45043 | F30: 350 subs at $39.99; converts to $49.99 Standard Jan 2027
A31: Standard new subscribers ($49.99/yr) | B31: 5249 | C31: 56125 | D31: 104850 | E31: =B31+C31+D31 -> 166224 | F31: Ramp: 75→175/mo in 2027; $49.99/yr
A32: Student conversions (paid Yr 2, $49.99/yr) | B32: 0 | C32: 5249 | D32: 7498 | E32: =B32+C32+D32 -> 12747 | F32: 28% of free students convert; $49.99 Standard rate
A33: TOTAL GROSS REVENUE | B33: =SUM(B27:B32) -> 85804 | C33: =SUM(C27:C32) -> 89696 | D33: =SUM(D27:D32) -> 138118 | E33: =SUM(E27:E32) -> 313618
A35: YEAR 1-3 COST PROJECTION
A36: Platform fixed (hosting, licenses, ASRT IP, etc.) | B36: 1239 | C36: 1239 | D36: 1239 | E36: =B36+C36+D36 -> 3717 | F36: ~$103/mo. IP fee removed — General Sponsor, no annual fee.
A37: Content: pre-launch audit & refresh (one-time) | B37: 6000 | C37: 0 | D37: 0 | E37: =B37+C37+D37 -> 6000 | F37: 20 courses × ~$300 avg
A38: ASRT submission fees | B38: 1350 | C38: 5400 | D38: 5400 | E38: =B38+C38+D38 -> 12150 | F38: 6 courses Y1; 72 new/yr at 6/mo pace by Y2
A39: Ongoing new course pipeline (6/mo) | B39: 48600 | C39: 48600 | D39: 48600 | E39: =B39+C39+D39 -> 145800 | F39: 6 × $675 × 12 months (goal: 6/mo; guarantee: 2/mo min)
A40: Claude API & AI tools | B40: 900 | C40: 900 | D40: 900 | E40: =B40+C40+D40 -> 2700 | F40: $75/mo ongoing
A41: Stripe processing fees | B41: 3000 | C41: 8500 | D41: 13000 | E41: =B41+C41+D41 -> 24500 | F41: Grows with revenue
A42: Support (AI-assisted) | B42: 500 | C42: 1800 | D42: 3500 | E42: =B42+C42+D42 -> 5800 | F42: Scales with subscriber count
A43: Catalyst management fee | B43: 9000 | C43: 21000 | D43: 30000 | E43: =B43+C43+D43 -> 60000 | F43: Tiered: $0→$1.5k→$2.5k/mo
A44: TOTAL COSTS | B44: =SUM(B36:B43) -> 70589 | C44: =SUM(C36:C43) -> 87439 | D44: =SUM(D36:D43) -> 102639 | E44: =SUM(E36:E43) -> 260667
...

Sheet Content Pipeline Economics
A1: TechCElerate — Content Pipeline Economics | AI-Assisted vs. Traditional
A3: COST COMPARISON: Traditional vs. AI-Assisted Pipeline
A4: Cost Element | B4: Traditional | C4: AI-Assisted | D4: Savings | E4: Savings % | F4: Notes
A5: Content drafting (per 1-CE course) | B5: 4000 | C5: 150 | D5: 3850 | E5: 0.9625 | F5: SME writes from scratch vs. AI drafts, human edits
A6: SME clinical review | B6: 0 | C6: 350 | D6: -350 | E6: 0 | F6: Included in trad. rate vs. dedicated review step
A7: Editing & formatting (AMA 11th ed.) | B7: 300 | C7: 75 | D7: 225 | E7: 0.75 | F7: Full edit vs. AI auto-format + spot-check
A8: ASRT submission fee (per course, avg) | B8: 225 | C8: 225 | D8: 0 | E8: 0 | F8: Fixed ASRT cost — not reducible
A9: LMS packaging & deployment | B9: 150 | C9: 30 | D9: 120 | E9: 0.8 | F9: Manual HTML vs. API-automated
A10: Post-test generation | B10: 200 | C10: 50 | D10: 150 | E10: 0.75 | F10: Manual question writing vs. AI + SME validation
A11: TOTAL PER 1-CE COURSE | B11: 4875 | C11: 880 | D11: 3995 | E11: 0.81948718 | F11: Cost per course fully-loaded
A13: ANNUAL CONTENT PIPELINE COST (6 NEW COURSES/MONTH = 72/YEAR)
A14: New course AI pipeline (72 × $675) | B14: 48600 | C14: All-in per course: AI draft + SME review + edit + ASRT
A15: Traditional equivalent (72 × $4,875) | B15: 351000 | C15: What the same 72-course output would cost with traditional writers
A16: Annual savings vs. traditional | B16: 302400 | C16: $302,400/year saved by AI pipeline at 6 courses/month
A17: 20-course launch refresh (one-time) | B17: 6000 | C17: Freshness audit + AI update + SME sign-off
A18: ASRT annual renewal (20 courses, avg $225) | B18: 4500 | C18: Keep approvals current — 20 × $225 avg renewal
A19: Total annual content budget (steady-state) | B19: 53100 | C19: New pipeline (72 courses) + ASRT renewals (20 existing × $225 avg)

Sheet Student & New Grad Pipeline
A1: TechCElerate — Student & New Grad Pipeline | Exam Prep Funnel → Free Year 1 → Paid Conversion
A2: 🔵 Blue = Input | ⚫ Black = Formula | 🟡 Yellow background = key assumption | 🟢 Green = linked from other sheets
A4: SECTION 1 — MARKET SIZE: New RT Graduates Entering Workforce
A5: Parameter | B5: Value | C5: Unit | D5: Notes / Source
A6: ARRT total registered credentials (2025) | B6: 360000 | C6: credentials | D6: Source: ARRT Annual Report. Includes multi-credential holders.
A7: Estimated employed radiologic technologists (BLS 2024) | B7: 228000 | C7: RTs | D7: BLS OES data — update annually
A8: Estimated new ARRT credentials issued per year | B8: 17000 | C8: new creds/yr | D8: ~5% of total base. Includes new grads + career changers.
A9: New grads entering workforce from RT programs/yr | B9: 14000 | C9: new grads/yr | D9: Subset of above — accredited RT program completers
A10: Active accredited RT programs (JRCERT) | B10: 680 | C10: programs | D10: Source: JRCERT website — verify annually
A11: Avg graduates per program per year | B11: =B9/B10 -> 20.588235 | C11: grads/program | D11: Rough average, varies widely by program size. Source: JRCERT.
A13: SECTION 2 — ACQUISITION FUNNEL ASSUMPTIONS
A14: Parameter | B14: Value | C14: Unit | D14: Notes / Source
A15: ── EXAM PREP TOOL (Top of Funnel) | D15: Free ARRT registry prep — practice questions, category scores, study guide
A16: RT students who find exam prep tool/month | B16: 150 | C16: students/mo | D16: SEO + RT program outreach + Facebook groups. Conservative ramp.
A17: Email capture rate (tool users → registered) | B17: 0.7 | C17: % | D17: 70% — high intent users, the tool requires registration to save scores
A18: Registered exam prep users/month | B18: =B16*B17 -> 105 | C18: users/mo | D18: Formula: tool users × capture rate
A19: ── FREE YEAR 1 (.edu / new grad) | D19: Students + new grads get Year 1 free. No CE credits until credentialed.
A20: Exam prep registrants who convert to Free Year 1 | B20: 0.5 | C20: % | D20: 50% — they register for CE access once they know about it
A21: Direct new grad signups/month (non-exam prep path) | B21: 30 | C21: subs/mo | D21: LinkedIn outreach, RT program partnerships, word-of-mouth
A22: Total new free students/month | B22: =B18*B20+B21 -> 82.5 | C22: subs/mo | D22: Formula: (exam prep converted) + direct signups
A23: ── YEAR 2 PAID CONVERSION | D23: Free students convert to paid Standard ($39.99/yr) in Year 2
A24: Year 1 → Year 2 paid conversion rate | B24: 0.28 | C24: % | D24: 28% base. Higher than cold traffic — brand loyalty built during free year.
A25: Conversion price (Standard rate) | B25: =Assumptions!B12 -> 49.99 | C25: $/yr | D25: Links to Standard price in Assumptions sheet
A26: ── LONG-TERM RETENTION
A27: Annual churn — converted student subscribers | B27: 0.15 | C27: % | D27: 15% — lower than avg Standard churn; loyalty from free year
A28: Average RT career length | B28: 35 | C28: years | D28: Industry estimate — many RTs career until retirement
A29: Active CE years (after credential, to retirement) | B29: 33 | C29: years | D29: Career length minus 2 years pre-credential
A30: ── SOCIAL MEDIA VIRAL MULTIPLIER | D30: Cohort sharing — RTs in same program share tools with classmates
A31: Avg referrals per student (cohort sharing) | B31: 2.5 | C31: referrals/student | D31: RT programs are tight-knit cohorts. One person shares with class.
A32: Referral → registration conversion rate | B32: 0.35 | C32: % | D32: 35% of referred students register
A33: Effective monthly reach multiplier | B33: =1+B31*B32 -> 1.875 | C33: x | D33: Total reach = direct + viral. Formula: 1 + (referrals × conversion)
A35: SECTION 3 — ANNUAL COHORT MODEL (5-Year View)
A36: Metric | B36: 2026 (Jul–Dec) | C36: 2027 (Full Year) | D36: 2028 (Full Year) | E36: 2029 (Full Year) | F36: 2030 (Full Year) | G36: Notes
A37: ── ACQUISITION | G37: Monthly figures × months active per year
A38: Free students acquired (cumulative) | B38: =B22*6 -> 495 | C38: =B22*12 -> 990 | D38: =B22*12 -> 990 | E38: =B22*12 -> 990 | F38: =B22*12 -> 990 | G38: Formula: free/month × months. 6 mo in 2026 (Jul–Dec).
A39: Cumulative free student base (end of period) | B39: =B38 -> 495 | C39: =B39+C38 -> 1485 | D39: =C39+D38 -> 2475 | E39: =D39+E38 -> 3465 | F39: =E39+F38 -> 4455 | G39: Running total of free students in pipeline
A40: ── PAID CONVERSIONS (Year 2 converts) | G40: Students who complete free year → paid subscribers
A41: New paid converts this year | B41: 0 | C41: =B38*B24 -> 138.6 | D41: =C38*B24 -> 277.2 | E41: =D38*B24 -> 277.2 | F41: =E38*B24 -> 277.2 | G41: Formula: prior year free cohort × conversion rate. No converts in 2026.
A42: Churned paid converts (from prior cohorts) | B42: 0 | C42: 0 | D42: =D41*B27 -> 41.58 | E42: =(D41+E41)*B27 -> 83.16 | F42: =(D41+E41+F41)*B27 -> 124.74 | G42: Formula: cumulative paid converts × Standard churn rate
A43: Net new paid student subscribers | B43: =C41-C42 -> 138.6 | C43: =D41-D42 -> 235.62 | D43: =E41-E42 -> 194.04 | E43: =F41-F42 -> 152.46 | F43: =F41-F42 -> 152.46 | G43: New converts minus churn
...
